{
 "cells": [
  {
   "cell_type": "markdown",
   "metadata": {
    "isInteractiveWindowMessageCell": true
   },
   "source": [
    "Connected to Python 3.12.0"
   ]
  },
  {
   "cell_type": "code",
   "execution_count": 1,
   "metadata": {},
   "outputs": [
    {
     "name": "stderr",
     "output_type": "stream",
     "text": [
      "2024-04-08 17:01:02,829 (__init__.py:1147 MainThread) ERROR - TeleBot: \"Threaded polling exception: A request to the Telegram API was unsuccessful. Error code: 409. Description: Conflict: terminated by other getUpdates request; make sure that only one bot instance is running\"\n",
      "2024-04-08 17:01:02,832 (__init__.py:1149 MainThread) ERROR - TeleBot: \"Exception traceback:\n",
      "Traceback (most recent call last):\n",
      "  File \"c:\\Users\\i.fediunin\\AppData\\Local\\Programs\\Python\\Python312\\Lib\\site-packages\\telebot\\__init__.py\", line 1140, in __threaded_polling\n",
      "    polling_thread.raise_exceptions()\n",
      "  File \"c:\\Users\\i.fediunin\\AppData\\Local\\Programs\\Python\\Python312\\Lib\\site-packages\\telebot\\util.py\", line 110, in raise_exceptions\n",
      "    raise self.exception_info\n",
      "  File \"c:\\Users\\i.fediunin\\AppData\\Local\\Programs\\Python\\Python312\\Lib\\site-packages\\telebot\\util.py\", line 92, in run\n",
      "    task(*args, **kwargs)\n",
      "  File \"c:\\Users\\i.fediunin\\AppData\\Local\\Programs\\Python\\Python312\\Lib\\site-packages\\telebot\\__init__.py\", line 661, in __retrieve_updates\n",
      "    updates = self.get_updates(offset=(self.last_update_id + 1),\n",
      "             ^^^^^^^^^^^^^^^^^^^^^^^^^^^^^^^^^^^^^^^^^^^^^^^^^^^\n",
      "  File \"c:\\Users\\i.fediunin\\AppData\\Local\\Programs\\Python\\Python312\\Lib\\site-packages\\telebot\\__init__.py\", line 633, in get_updates\n",
      "    json_updates = apihelper.get_updates(\n",
      "                   ^^^^^^^^^^^^^^^^^^^^^^\n",
      "  File \"c:\\Users\\i.fediunin\\AppData\\Local\\Programs\\Python\\Python312\\Lib\\site-packages\\telebot\\apihelper.py\", line 321, in get_updates\n",
      "    return _make_request(token, method_url, params=payload)\n",
      "           ^^^^^^^^^^^^^^^^^^^^^^^^^^^^^^^^^^^^^^^^^^^^^^^^\n",
      "  File \"c:\\Users\\i.fediunin\\AppData\\Local\\Programs\\Python\\Python312\\Lib\\site-packages\\telebot\\apihelper.py\", line 164, in _make_request\n",
      "    json_result = _check_result(method_name, result)\n",
      "                  ^^^^^^^^^^^^^^^^^^^^^^^^^^^^^^^^^^\n",
      "  File \"c:\\Users\\i.fediunin\\AppData\\Local\\Programs\\Python\\Python312\\Lib\\site-packages\\telebot\\apihelper.py\", line 191, in _check_result\n",
      "    raise ApiTelegramException(method_name, result, result_json)\n",
      "telebot.apihelper.ApiTelegramException: A request to the Telegram API was unsuccessful. Error code: 409. Description: Conflict: terminated by other getUpdates request; make sure that only one bot instance is running\n",
      "\"\n",
      "2024-04-08 17:01:06,818 (__init__.py:1147 MainThread) ERROR - TeleBot: \"Threaded polling exception: A request to the Telegram API was unsuccessful. Error code: 409. Description: Conflict: terminated by other getUpdates request; make sure that only one bot instance is running\"\n",
      "2024-04-08 17:01:06,820 (__init__.py:1149 MainThread) ERROR - TeleBot: \"Exception traceback:\n",
      "Traceback (most recent call last):\n",
      "  File \"c:\\Users\\i.fediunin\\AppData\\Local\\Programs\\Python\\Python312\\Lib\\site-packages\\telebot\\__init__.py\", line 1140, in __threaded_polling\n",
      "    polling_thread.raise_exceptions()\n",
      "  File \"c:\\Users\\i.fediunin\\AppData\\Local\\Programs\\Python\\Python312\\Lib\\site-packages\\telebot\\util.py\", line 110, in raise_exceptions\n",
      "    raise self.exception_info\n",
      "  File \"c:\\Users\\i.fediunin\\AppData\\Local\\Programs\\Python\\Python312\\Lib\\site-packages\\telebot\\util.py\", line 92, in run\n",
      "    task(*args, **kwargs)\n",
      "  File \"c:\\Users\\i.fediunin\\AppData\\Local\\Programs\\Python\\Python312\\Lib\\site-packages\\telebot\\__init__.py\", line 661, in __retrieve_updates\n",
      "    updates = self.get_updates(offset=(self.last_update_id + 1),\n",
      "             ^^^^^^^^^^^^^^^^^^^^^^^^^^^^^^^^^^^^^^^^^^^^^^^^^^^\n",
      "  File \"c:\\Users\\i.fediunin\\AppData\\Local\\Programs\\Python\\Python312\\Lib\\site-packages\\telebot\\__init__.py\", line 633, in get_updates\n",
      "    json_updates = apihelper.get_updates(\n",
      "                   ^^^^^^^^^^^^^^^^^^^^^^\n",
      "  File \"c:\\Users\\i.fediunin\\AppData\\Local\\Programs\\Python\\Python312\\Lib\\site-packages\\telebot\\apihelper.py\", line 321, in get_updates\n",
      "    return _make_request(token, method_url, params=payload)\n",
      "           ^^^^^^^^^^^^^^^^^^^^^^^^^^^^^^^^^^^^^^^^^^^^^^^^\n",
      "  File \"c:\\Users\\i.fediunin\\AppData\\Local\\Programs\\Python\\Python312\\Lib\\site-packages\\telebot\\apihelper.py\", line 164, in _make_request\n",
      "    json_result = _check_result(method_name, result)\n",
      "                  ^^^^^^^^^^^^^^^^^^^^^^^^^^^^^^^^^^\n",
      "  File \"c:\\Users\\i.fediunin\\AppData\\Local\\Programs\\Python\\Python312\\Lib\\site-packages\\telebot\\apihelper.py\", line 191, in _check_result\n",
      "    raise ApiTelegramException(method_name, result, result_json)\n",
      "telebot.apihelper.ApiTelegramException: A request to the Telegram API was unsuccessful. Error code: 409. Description: Conflict: terminated by other getUpdates request; make sure that only one bot instance is running\n",
      "\"\n",
      "2024-04-08 17:01:11,454 (__init__.py:1147 MainThread) ERROR - TeleBot: \"Threaded polling exception: A request to the Telegram API was unsuccessful. Error code: 409. Description: Conflict: terminated by other getUpdates request; make sure that only one bot instance is running\"\n",
      "2024-04-08 17:01:11,458 (__init__.py:1149 MainThread) ERROR - TeleBot: \"Exception traceback:\n",
      "Traceback (most recent call last):\n",
      "  File \"c:\\Users\\i.fediunin\\AppData\\Local\\Programs\\Python\\Python312\\Lib\\site-packages\\telebot\\__init__.py\", line 1140, in __threaded_polling\n",
      "    polling_thread.raise_exceptions()\n",
      "  File \"c:\\Users\\i.fediunin\\AppData\\Local\\Programs\\Python\\Python312\\Lib\\site-packages\\telebot\\util.py\", line 110, in raise_exceptions\n",
      "    raise self.exception_info\n",
      "  File \"c:\\Users\\i.fediunin\\AppData\\Local\\Programs\\Python\\Python312\\Lib\\site-packages\\telebot\\util.py\", line 92, in run\n",
      "    task(*args, **kwargs)\n",
      "  File \"c:\\Users\\i.fediunin\\AppData\\Local\\Programs\\Python\\Python312\\Lib\\site-packages\\telebot\\__init__.py\", line 661, in __retrieve_updates\n",
      "    updates = self.get_updates(offset=(self.last_update_id + 1),\n",
      "             ^^^^^^^^^^^^^^^^^^^^^^^^^^^^^^^^^^^^^^^^^^^^^^^^^^^\n",
      "  File \"c:\\Users\\i.fediunin\\AppData\\Local\\Programs\\Python\\Python312\\Lib\\site-packages\\telebot\\__init__.py\", line 633, in get_updates\n",
      "    json_updates = apihelper.get_updates(\n",
      "                   ^^^^^^^^^^^^^^^^^^^^^^\n",
      "  File \"c:\\Users\\i.fediunin\\AppData\\Local\\Programs\\Python\\Python312\\Lib\\site-packages\\telebot\\apihelper.py\", line 321, in get_updates\n",
      "    return _make_request(token, method_url, params=payload)\n",
      "           ^^^^^^^^^^^^^^^^^^^^^^^^^^^^^^^^^^^^^^^^^^^^^^^^\n",
      "  File \"c:\\Users\\i.fediunin\\AppData\\Local\\Programs\\Python\\Python312\\Lib\\site-packages\\telebot\\apihelper.py\", line 164, in _make_request\n",
      "    json_result = _check_result(method_name, result)\n",
      "                  ^^^^^^^^^^^^^^^^^^^^^^^^^^^^^^^^^^\n",
      "  File \"c:\\Users\\i.fediunin\\AppData\\Local\\Programs\\Python\\Python312\\Lib\\site-packages\\telebot\\apihelper.py\", line 191, in _check_result\n",
      "    raise ApiTelegramException(method_name, result, result_json)\n",
      "telebot.apihelper.ApiTelegramException: A request to the Telegram API was unsuccessful. Error code: 409. Description: Conflict: terminated by other getUpdates request; make sure that only one bot instance is running\n",
      "\"\n",
      "2024-04-08 17:01:17,682 (__init__.py:1147 MainThread) ERROR - TeleBot: \"Threaded polling exception: A request to the Telegram API was unsuccessful. Error code: 409. Description: Conflict: terminated by other getUpdates request; make sure that only one bot instance is running\"\n",
      "2024-04-08 17:01:17,684 (__init__.py:1149 MainThread) ERROR - TeleBot: \"Exception traceback:\n",
      "Traceback (most recent call last):\n",
      "  File \"c:\\Users\\i.fediunin\\AppData\\Local\\Programs\\Python\\Python312\\Lib\\site-packages\\telebot\\__init__.py\", line 1140, in __threaded_polling\n",
      "    polling_thread.raise_exceptions()\n",
      "  File \"c:\\Users\\i.fediunin\\AppData\\Local\\Programs\\Python\\Python312\\Lib\\site-packages\\telebot\\util.py\", line 110, in raise_exceptions\n",
      "    raise self.exception_info\n",
      "  File \"c:\\Users\\i.fediunin\\AppData\\Local\\Programs\\Python\\Python312\\Lib\\site-packages\\telebot\\util.py\", line 92, in run\n",
      "    task(*args, **kwargs)\n",
      "  File \"c:\\Users\\i.fediunin\\AppData\\Local\\Programs\\Python\\Python312\\Lib\\site-packages\\telebot\\__init__.py\", line 661, in __retrieve_updates\n",
      "    updates = self.get_updates(offset=(self.last_update_id + 1),\n",
      "             ^^^^^^^^^^^^^^^^^^^^^^^^^^^^^^^^^^^^^^^^^^^^^^^^^^^\n",
      "  File \"c:\\Users\\i.fediunin\\AppData\\Local\\Programs\\Python\\Python312\\Lib\\site-packages\\telebot\\__init__.py\", line 633, in get_updates\n",
      "    json_updates = apihelper.get_updates(\n",
      "                   ^^^^^^^^^^^^^^^^^^^^^^\n",
      "  File \"c:\\Users\\i.fediunin\\AppData\\Local\\Programs\\Python\\Python312\\Lib\\site-packages\\telebot\\apihelper.py\", line 321, in get_updates\n",
      "    return _make_request(token, method_url, params=payload)\n",
      "           ^^^^^^^^^^^^^^^^^^^^^^^^^^^^^^^^^^^^^^^^^^^^^^^^\n",
      "  File \"c:\\Users\\i.fediunin\\AppData\\Local\\Programs\\Python\\Python312\\Lib\\site-packages\\telebot\\apihelper.py\", line 164, in _make_request\n",
      "    json_result = _check_result(method_name, result)\n",
      "                  ^^^^^^^^^^^^^^^^^^^^^^^^^^^^^^^^^^\n",
      "  File \"c:\\Users\\i.fediunin\\AppData\\Local\\Programs\\Python\\Python312\\Lib\\site-packages\\telebot\\apihelper.py\", line 191, in _check_result\n",
      "    raise ApiTelegramException(method_name, result, result_json)\n",
      "telebot.apihelper.ApiTelegramException: A request to the Telegram API was unsuccessful. Error code: 409. Description: Conflict: terminated by other getUpdates request; make sure that only one bot instance is running\n",
      "\"\n",
      "2024-04-08 17:01:23,927 (__init__.py:1147 MainThread) ERROR - TeleBot: \"Threaded polling exception: A request to the Telegram API was unsuccessful. Error code: 409. Description: Conflict: terminated by other getUpdates request; make sure that only one bot instance is running\"\n",
      "2024-04-08 17:01:23,929 (__init__.py:1149 MainThread) ERROR - TeleBot: \"Exception traceback:\n",
      "Traceback (most recent call last):\n",
      "  File \"c:\\Users\\i.fediunin\\AppData\\Local\\Programs\\Python\\Python312\\Lib\\site-packages\\telebot\\__init__.py\", line 1140, in __threaded_polling\n",
      "    polling_thread.raise_exceptions()\n",
      "  File \"c:\\Users\\i.fediunin\\AppData\\Local\\Programs\\Python\\Python312\\Lib\\site-packages\\telebot\\util.py\", line 110, in raise_exceptions\n",
      "    raise self.exception_info\n",
      "  File \"c:\\Users\\i.fediunin\\AppData\\Local\\Programs\\Python\\Python312\\Lib\\site-packages\\telebot\\util.py\", line 92, in run\n",
      "    task(*args, **kwargs)\n",
      "  File \"c:\\Users\\i.fediunin\\AppData\\Local\\Programs\\Python\\Python312\\Lib\\site-packages\\telebot\\__init__.py\", line 661, in __retrieve_updates\n",
      "    updates = self.get_updates(offset=(self.last_update_id + 1),\n",
      "             ^^^^^^^^^^^^^^^^^^^^^^^^^^^^^^^^^^^^^^^^^^^^^^^^^^^\n",
      "  File \"c:\\Users\\i.fediunin\\AppData\\Local\\Programs\\Python\\Python312\\Lib\\site-packages\\telebot\\__init__.py\", line 633, in get_updates\n",
      "    json_updates = apihelper.get_updates(\n",
      "                   ^^^^^^^^^^^^^^^^^^^^^^\n",
      "  File \"c:\\Users\\i.fediunin\\AppData\\Local\\Programs\\Python\\Python312\\Lib\\site-packages\\telebot\\apihelper.py\", line 321, in get_updates\n",
      "    return _make_request(token, method_url, params=payload)\n",
      "           ^^^^^^^^^^^^^^^^^^^^^^^^^^^^^^^^^^^^^^^^^^^^^^^^\n",
      "  File \"c:\\Users\\i.fediunin\\AppData\\Local\\Programs\\Python\\Python312\\Lib\\site-packages\\telebot\\apihelper.py\", line 164, in _make_request\n",
      "    json_result = _check_result(method_name, result)\n",
      "                  ^^^^^^^^^^^^^^^^^^^^^^^^^^^^^^^^^^\n",
      "  File \"c:\\Users\\i.fediunin\\AppData\\Local\\Programs\\Python\\Python312\\Lib\\site-packages\\telebot\\apihelper.py\", line 191, in _check_result\n",
      "    raise ApiTelegramException(method_name, result, result_json)\n",
      "telebot.apihelper.ApiTelegramException: A request to the Telegram API was unsuccessful. Error code: 409. Description: Conflict: terminated by other getUpdates request; make sure that only one bot instance is running\n",
      "\"\n",
      "2024-04-08 17:01:36,111 (__init__.py:1147 MainThread) ERROR - TeleBot: \"Threaded polling exception: A request to the Telegram API was unsuccessful. Error code: 409. Description: Conflict: terminated by other getUpdates request; make sure that only one bot instance is running\"\n",
      "2024-04-08 17:01:36,113 (__init__.py:1149 MainThread) ERROR - TeleBot: \"Exception traceback:\n",
      "Traceback (most recent call last):\n",
      "  File \"c:\\Users\\i.fediunin\\AppData\\Local\\Programs\\Python\\Python312\\Lib\\site-packages\\telebot\\__init__.py\", line 1140, in __threaded_polling\n",
      "    polling_thread.raise_exceptions()\n",
      "  File \"c:\\Users\\i.fediunin\\AppData\\Local\\Programs\\Python\\Python312\\Lib\\site-packages\\telebot\\util.py\", line 110, in raise_exceptions\n",
      "    raise self.exception_info\n",
      "  File \"c:\\Users\\i.fediunin\\AppData\\Local\\Programs\\Python\\Python312\\Lib\\site-packages\\telebot\\util.py\", line 92, in run\n",
      "    task(*args, **kwargs)\n",
      "  File \"c:\\Users\\i.fediunin\\AppData\\Local\\Programs\\Python\\Python312\\Lib\\site-packages\\telebot\\__init__.py\", line 661, in __retrieve_updates\n",
      "    updates = self.get_updates(offset=(self.last_update_id + 1),\n",
      "             ^^^^^^^^^^^^^^^^^^^^^^^^^^^^^^^^^^^^^^^^^^^^^^^^^^^\n",
      "  File \"c:\\Users\\i.fediunin\\AppData\\Local\\Programs\\Python\\Python312\\Lib\\site-packages\\telebot\\__init__.py\", line 633, in get_updates\n",
      "    json_updates = apihelper.get_updates(\n",
      "                   ^^^^^^^^^^^^^^^^^^^^^^\n",
      "  File \"c:\\Users\\i.fediunin\\AppData\\Local\\Programs\\Python\\Python312\\Lib\\site-packages\\telebot\\apihelper.py\", line 321, in get_updates\n",
      "    return _make_request(token, method_url, params=payload)\n",
      "           ^^^^^^^^^^^^^^^^^^^^^^^^^^^^^^^^^^^^^^^^^^^^^^^^\n",
      "  File \"c:\\Users\\i.fediunin\\AppData\\Local\\Programs\\Python\\Python312\\Lib\\site-packages\\telebot\\apihelper.py\", line 164, in _make_request\n",
      "    json_result = _check_result(method_name, result)\n",
      "                  ^^^^^^^^^^^^^^^^^^^^^^^^^^^^^^^^^^\n",
      "  File \"c:\\Users\\i.fediunin\\AppData\\Local\\Programs\\Python\\Python312\\Lib\\site-packages\\telebot\\apihelper.py\", line 191, in _check_result\n",
      "    raise ApiTelegramException(method_name, result, result_json)\n",
      "telebot.apihelper.ApiTelegramException: A request to the Telegram API was unsuccessful. Error code: 409. Description: Conflict: terminated by other getUpdates request; make sure that only one bot instance is running\n",
      "\"\n",
      "2024-04-08 17:02:00,276 (__init__.py:1147 MainThread) ERROR - TeleBot: \"Threaded polling exception: A request to the Telegram API was unsuccessful. Error code: 409. Description: Conflict: terminated by other getUpdates request; make sure that only one bot instance is running\"\n",
      "2024-04-08 17:02:00,278 (__init__.py:1149 MainThread) ERROR - TeleBot: \"Exception traceback:\n",
      "Traceback (most recent call last):\n",
      "  File \"c:\\Users\\i.fediunin\\AppData\\Local\\Programs\\Python\\Python312\\Lib\\site-packages\\telebot\\__init__.py\", line 1140, in __threaded_polling\n",
      "    polling_thread.raise_exceptions()\n",
      "  File \"c:\\Users\\i.fediunin\\AppData\\Local\\Programs\\Python\\Python312\\Lib\\site-packages\\telebot\\util.py\", line 110, in raise_exceptions\n",
      "    raise self.exception_info\n",
      "  File \"c:\\Users\\i.fediunin\\AppData\\Local\\Programs\\Python\\Python312\\Lib\\site-packages\\telebot\\util.py\", line 92, in run\n",
      "    task(*args, **kwargs)\n",
      "  File \"c:\\Users\\i.fediunin\\AppData\\Local\\Programs\\Python\\Python312\\Lib\\site-packages\\telebot\\__init__.py\", line 661, in __retrieve_updates\n",
      "    updates = self.get_updates(offset=(self.last_update_id + 1),\n",
      "             ^^^^^^^^^^^^^^^^^^^^^^^^^^^^^^^^^^^^^^^^^^^^^^^^^^^\n",
      "  File \"c:\\Users\\i.fediunin\\AppData\\Local\\Programs\\Python\\Python312\\Lib\\site-packages\\telebot\\__init__.py\", line 633, in get_updates\n",
      "    json_updates = apihelper.get_updates(\n",
      "                   ^^^^^^^^^^^^^^^^^^^^^^\n",
      "  File \"c:\\Users\\i.fediunin\\AppData\\Local\\Programs\\Python\\Python312\\Lib\\site-packages\\telebot\\apihelper.py\", line 321, in get_updates\n",
      "    return _make_request(token, method_url, params=payload)\n",
      "           ^^^^^^^^^^^^^^^^^^^^^^^^^^^^^^^^^^^^^^^^^^^^^^^^\n",
      "  File \"c:\\Users\\i.fediunin\\AppData\\Local\\Programs\\Python\\Python312\\Lib\\site-packages\\telebot\\apihelper.py\", line 164, in _make_request\n",
      "    json_result = _check_result(method_name, result)\n",
      "                  ^^^^^^^^^^^^^^^^^^^^^^^^^^^^^^^^^^\n",
      "  File \"c:\\Users\\i.fediunin\\AppData\\Local\\Programs\\Python\\Python312\\Lib\\site-packages\\telebot\\apihelper.py\", line 191, in _check_result\n",
      "    raise ApiTelegramException(method_name, result, result_json)\n",
      "telebot.apihelper.ApiTelegramException: A request to the Telegram API was unsuccessful. Error code: 409. Description: Conflict: terminated by other getUpdates request; make sure that only one bot instance is running\n",
      "\"\n",
      "2024-04-08 17:02:48,507 (__init__.py:1147 MainThread) ERROR - TeleBot: \"Threaded polling exception: A request to the Telegram API was unsuccessful. Error code: 409. Description: Conflict: terminated by other getUpdates request; make sure that only one bot instance is running\"\n",
      "2024-04-08 17:02:48,509 (__init__.py:1149 MainThread) ERROR - TeleBot: \"Exception traceback:\n",
      "Traceback (most recent call last):\n",
      "  File \"c:\\Users\\i.fediunin\\AppData\\Local\\Programs\\Python\\Python312\\Lib\\site-packages\\telebot\\__init__.py\", line 1140, in __threaded_polling\n",
      "    polling_thread.raise_exceptions()\n",
      "  File \"c:\\Users\\i.fediunin\\AppData\\Local\\Programs\\Python\\Python312\\Lib\\site-packages\\telebot\\util.py\", line 110, in raise_exceptions\n",
      "    raise self.exception_info\n",
      "  File \"c:\\Users\\i.fediunin\\AppData\\Local\\Programs\\Python\\Python312\\Lib\\site-packages\\telebot\\util.py\", line 92, in run\n",
      "    task(*args, **kwargs)\n",
      "  File \"c:\\Users\\i.fediunin\\AppData\\Local\\Programs\\Python\\Python312\\Lib\\site-packages\\telebot\\__init__.py\", line 661, in __retrieve_updates\n",
      "    updates = self.get_updates(offset=(self.last_update_id + 1),\n",
      "             ^^^^^^^^^^^^^^^^^^^^^^^^^^^^^^^^^^^^^^^^^^^^^^^^^^^\n",
      "  File \"c:\\Users\\i.fediunin\\AppData\\Local\\Programs\\Python\\Python312\\Lib\\site-packages\\telebot\\__init__.py\", line 633, in get_updates\n",
      "    json_updates = apihelper.get_updates(\n",
      "                   ^^^^^^^^^^^^^^^^^^^^^^\n",
      "  File \"c:\\Users\\i.fediunin\\AppData\\Local\\Programs\\Python\\Python312\\Lib\\site-packages\\telebot\\apihelper.py\", line 321, in get_updates\n",
      "    return _make_request(token, method_url, params=payload)\n",
      "           ^^^^^^^^^^^^^^^^^^^^^^^^^^^^^^^^^^^^^^^^^^^^^^^^\n",
      "  File \"c:\\Users\\i.fediunin\\AppData\\Local\\Programs\\Python\\Python312\\Lib\\site-packages\\telebot\\apihelper.py\", line 164, in _make_request\n",
      "    json_result = _check_result(method_name, result)\n",
      "                  ^^^^^^^^^^^^^^^^^^^^^^^^^^^^^^^^^^\n",
      "  File \"c:\\Users\\i.fediunin\\AppData\\Local\\Programs\\Python\\Python312\\Lib\\site-packages\\telebot\\apihelper.py\", line 191, in _check_result\n",
      "    raise ApiTelegramException(method_name, result, result_json)\n",
      "telebot.apihelper.ApiTelegramException: A request to the Telegram API was unsuccessful. Error code: 409. Description: Conflict: terminated by other getUpdates request; make sure that only one bot instance is running\n",
      "\"\n",
      "2024-04-08 17:03:51,937 (__init__.py:1147 MainThread) ERROR - TeleBot: \"Threaded polling exception: A request to the Telegram API was unsuccessful. Error code: 409. Description: Conflict: terminated by other getUpdates request; make sure that only one bot instance is running\"\n",
      "2024-04-08 17:03:51,938 (__init__.py:1149 MainThread) ERROR - TeleBot: \"Exception traceback:\n",
      "Traceback (most recent call last):\n",
      "  File \"c:\\Users\\i.fediunin\\AppData\\Local\\Programs\\Python\\Python312\\Lib\\site-packages\\telebot\\__init__.py\", line 1140, in __threaded_polling\n",
      "    polling_thread.raise_exceptions()\n",
      "  File \"c:\\Users\\i.fediunin\\AppData\\Local\\Programs\\Python\\Python312\\Lib\\site-packages\\telebot\\util.py\", line 110, in raise_exceptions\n",
      "    raise self.exception_info\n",
      "  File \"c:\\Users\\i.fediunin\\AppData\\Local\\Programs\\Python\\Python312\\Lib\\site-packages\\telebot\\util.py\", line 92, in run\n",
      "    task(*args, **kwargs)\n",
      "  File \"c:\\Users\\i.fediunin\\AppData\\Local\\Programs\\Python\\Python312\\Lib\\site-packages\\telebot\\__init__.py\", line 661, in __retrieve_updates\n",
      "    updates = self.get_updates(offset=(self.last_update_id + 1),\n",
      "             ^^^^^^^^^^^^^^^^^^^^^^^^^^^^^^^^^^^^^^^^^^^^^^^^^^^\n",
      "  File \"c:\\Users\\i.fediunin\\AppData\\Local\\Programs\\Python\\Python312\\Lib\\site-packages\\telebot\\__init__.py\", line 633, in get_updates\n",
      "    json_updates = apihelper.get_updates(\n",
      "                   ^^^^^^^^^^^^^^^^^^^^^^\n",
      "  File \"c:\\Users\\i.fediunin\\AppData\\Local\\Programs\\Python\\Python312\\Lib\\site-packages\\telebot\\apihelper.py\", line 321, in get_updates\n",
      "    return _make_request(token, method_url, params=payload)\n",
      "           ^^^^^^^^^^^^^^^^^^^^^^^^^^^^^^^^^^^^^^^^^^^^^^^^\n",
      "  File \"c:\\Users\\i.fediunin\\AppData\\Local\\Programs\\Python\\Python312\\Lib\\site-packages\\telebot\\apihelper.py\", line 164, in _make_request\n",
      "    json_result = _check_result(method_name, result)\n",
      "                  ^^^^^^^^^^^^^^^^^^^^^^^^^^^^^^^^^^\n",
      "  File \"c:\\Users\\i.fediunin\\AppData\\Local\\Programs\\Python\\Python312\\Lib\\site-packages\\telebot\\apihelper.py\", line 191, in _check_result\n",
      "    raise ApiTelegramException(method_name, result, result_json)\n",
      "telebot.apihelper.ApiTelegramException: A request to the Telegram API was unsuccessful. Error code: 409. Description: Conflict: terminated by other getUpdates request; make sure that only one bot instance is running\n",
      "\"\n",
      "2024-04-08 17:04:55,383 (__init__.py:1147 MainThread) ERROR - TeleBot: \"Threaded polling exception: A request to the Telegram API was unsuccessful. Error code: 409. Description: Conflict: terminated by other getUpdates request; make sure that only one bot instance is running\"\n",
      "2024-04-08 17:04:55,385 (__init__.py:1149 MainThread) ERROR - TeleBot: \"Exception traceback:\n",
      "Traceback (most recent call last):\n",
      "  File \"c:\\Users\\i.fediunin\\AppData\\Local\\Programs\\Python\\Python312\\Lib\\site-packages\\telebot\\__init__.py\", line 1140, in __threaded_polling\n",
      "    polling_thread.raise_exceptions()\n",
      "  File \"c:\\Users\\i.fediunin\\AppData\\Local\\Programs\\Python\\Python312\\Lib\\site-packages\\telebot\\util.py\", line 110, in raise_exceptions\n",
      "    raise self.exception_info\n",
      "  File \"c:\\Users\\i.fediunin\\AppData\\Local\\Programs\\Python\\Python312\\Lib\\site-packages\\telebot\\util.py\", line 92, in run\n",
      "    task(*args, **kwargs)\n",
      "  File \"c:\\Users\\i.fediunin\\AppData\\Local\\Programs\\Python\\Python312\\Lib\\site-packages\\telebot\\__init__.py\", line 661, in __retrieve_updates\n",
      "    updates = self.get_updates(offset=(self.last_update_id + 1),\n",
      "             ^^^^^^^^^^^^^^^^^^^^^^^^^^^^^^^^^^^^^^^^^^^^^^^^^^^\n",
      "  File \"c:\\Users\\i.fediunin\\AppData\\Local\\Programs\\Python\\Python312\\Lib\\site-packages\\telebot\\__init__.py\", line 633, in get_updates\n",
      "    json_updates = apihelper.get_updates(\n",
      "                   ^^^^^^^^^^^^^^^^^^^^^^\n",
      "  File \"c:\\Users\\i.fediunin\\AppData\\Local\\Programs\\Python\\Python312\\Lib\\site-packages\\telebot\\apihelper.py\", line 321, in get_updates\n",
      "    return _make_request(token, method_url, params=payload)\n",
      "           ^^^^^^^^^^^^^^^^^^^^^^^^^^^^^^^^^^^^^^^^^^^^^^^^\n",
      "  File \"c:\\Users\\i.fediunin\\AppData\\Local\\Programs\\Python\\Python312\\Lib\\site-packages\\telebot\\apihelper.py\", line 164, in _make_request\n",
      "    json_result = _check_result(method_name, result)\n",
      "                  ^^^^^^^^^^^^^^^^^^^^^^^^^^^^^^^^^^\n",
      "  File \"c:\\Users\\i.fediunin\\AppData\\Local\\Programs\\Python\\Python312\\Lib\\site-packages\\telebot\\apihelper.py\", line 191, in _check_result\n",
      "    raise ApiTelegramException(method_name, result, result_json)\n",
      "telebot.apihelper.ApiTelegramException: A request to the Telegram API was unsuccessful. Error code: 409. Description: Conflict: terminated by other getUpdates request; make sure that only one bot instance is running\n",
      "\"\n",
      "2024-04-08 17:05:58,873 (__init__.py:1147 MainThread) ERROR - TeleBot: \"Threaded polling exception: A request to the Telegram API was unsuccessful. Error code: 409. Description: Conflict: terminated by other getUpdates request; make sure that only one bot instance is running\"\n",
      "2024-04-08 17:05:58,874 (__init__.py:1149 MainThread) ERROR - TeleBot: \"Exception traceback:\n",
      "Traceback (most recent call last):\n",
      "  File \"c:\\Users\\i.fediunin\\AppData\\Local\\Programs\\Python\\Python312\\Lib\\site-packages\\telebot\\__init__.py\", line 1140, in __threaded_polling\n",
      "    polling_thread.raise_exceptions()\n",
      "  File \"c:\\Users\\i.fediunin\\AppData\\Local\\Programs\\Python\\Python312\\Lib\\site-packages\\telebot\\util.py\", line 110, in raise_exceptions\n",
      "    raise self.exception_info\n",
      "  File \"c:\\Users\\i.fediunin\\AppData\\Local\\Programs\\Python\\Python312\\Lib\\site-packages\\telebot\\util.py\", line 92, in run\n",
      "    task(*args, **kwargs)\n",
      "  File \"c:\\Users\\i.fediunin\\AppData\\Local\\Programs\\Python\\Python312\\Lib\\site-packages\\telebot\\__init__.py\", line 661, in __retrieve_updates\n",
      "    updates = self.get_updates(offset=(self.last_update_id + 1),\n",
      "             ^^^^^^^^^^^^^^^^^^^^^^^^^^^^^^^^^^^^^^^^^^^^^^^^^^^\n",
      "  File \"c:\\Users\\i.fediunin\\AppData\\Local\\Programs\\Python\\Python312\\Lib\\site-packages\\telebot\\__init__.py\", line 633, in get_updates\n",
      "    json_updates = apihelper.get_updates(\n",
      "                   ^^^^^^^^^^^^^^^^^^^^^^\n",
      "  File \"c:\\Users\\i.fediunin\\AppData\\Local\\Programs\\Python\\Python312\\Lib\\site-packages\\telebot\\apihelper.py\", line 321, in get_updates\n",
      "    return _make_request(token, method_url, params=payload)\n",
      "           ^^^^^^^^^^^^^^^^^^^^^^^^^^^^^^^^^^^^^^^^^^^^^^^^\n",
      "  File \"c:\\Users\\i.fediunin\\AppData\\Local\\Programs\\Python\\Python312\\Lib\\site-packages\\telebot\\apihelper.py\", line 164, in _make_request\n",
      "    json_result = _check_result(method_name, result)\n",
      "                  ^^^^^^^^^^^^^^^^^^^^^^^^^^^^^^^^^^\n",
      "  File \"c:\\Users\\i.fediunin\\AppData\\Local\\Programs\\Python\\Python312\\Lib\\site-packages\\telebot\\apihelper.py\", line 191, in _check_result\n",
      "    raise ApiTelegramException(method_name, result, result_json)\n",
      "telebot.apihelper.ApiTelegramException: A request to the Telegram API was unsuccessful. Error code: 409. Description: Conflict: terminated by other getUpdates request; make sure that only one bot instance is running\n",
      "\"\n"
     ]
    }
   ],
   "source": [
    "import telebot\n",
    "bot = telebot.TeleBot(\"6477130900:AAFUZAmTtsJBjWkkuF7RSl2_4NUDjl6Dreg\")\n",
    "@bot.message_handler(commands=['start'])\n",
    "def main(message):\n",
    "    bot.send_message(message.chat.id,\"Hello, принцесса\")\n",
    "bot.polling(none_stop=True)    "
   ]
  }
 ],
 "metadata": {
  "kernelspec": {
   "display_name": "Python 3",
   "language": "python",
   "name": "python3"
  },
  "language_info": {
   "name": "python",
   "version": "3.12.0"
  }
 },
 "nbformat": 4,
 "nbformat_minor": 2
}
